<?xml version="1.0"?>
<robot  xmlns:xacro="http://www.ros.org/wiki/xacro" name="firefighter" >
	
<xacro:property name="width" value=".2" />


  <link name="base">
    <visual>
      <geometry>
       <mesh filename="file://$(find mycobot_description)/urdf/mycobot_pro_630/base.dae"/>
      </geometry>
    <origin xyz = "0 0 0 " rpy = " 1.5707 0 0"/>
    </visual>
    <collision>
    <geometry>
       <mesh filename="file://$(find mycobot_description)/urdf/mycobot_pro_630/base.dae"/>
      </geometry>
    <origin xyz = "0 0 0 " rpy = " 1.5707 0 0"/>
    </collision>
  </link>

  <link name="link1">
    <visual>
      <geometry>
       <mesh filename="file://$(find mycobot_description)/urdf/mycobot_pro_630/link1.dae"/>
      </geometry>
    <origin xyz = "0 0 -0.06 " rpy = "0 0 3.1415926"/>
    </visual>
     <collision>
      <geometry>
       <mesh filename="file://$(find mycobot_description)/urdf/mycobot_pro_630/link1.dae"/>
      </geometry>
    <origin xyz = "0 0 -0.06 " rpy = " 0 0 3.1415926"/>
    </collision>
  </link>


  <link name="link2">
    <visual>
      <geometry>
       <mesh filename="file://$(find mycobot_description)/urdf/mycobot_pro_630/link2.dae"/>
      </geometry>
    <origin xyz = "0 0 -0.0446 " rpy = " 0 -1.5707 -1.5707"/>
    </visual>
     <collision>
     <geometry>
       <mesh filename="file://$(find mycobot_description)/urdf/mycobot_pro_630/link2.dae"/>
      </geometry>
    <origin xyz = "0 0 -0.0446 " rpy = " 0 -1.5707 -1.5707"/>
    </collision>
  </link>


  <link name="link3">
    <visual>
      <geometry>
       <mesh filename="file://$(find mycobot_description)/urdf/mycobot_pro_630/link3.dae"/>
      </geometry>
    <origin xyz = "0 0 -0.0444 " rpy = " 0 1.5707 -1.5707"/>
    </visual>
     <collision>
      <geometry>
       <mesh filename="file://$(find mycobot_description)/urdf/mycobot_pro_630/link3.dae"/>
      </geometry>
    <origin xyz = "0 0 -0.0444 " rpy = "0 1.5707 -1.5707"/>
    </collision>
  </link>


<link name="link4">
    <visual>
      <geometry>
       <mesh filename="file://$(find mycobot_description)/urdf/mycobot_pro_630/link4.dae"/>
      </geometry>
    <origin xyz = "0 0 0.041 " rpy = " -1.5707 0 1.5707"/>
    </visual>
     <collision>
     <geometry>
       <mesh filename="file://$(find mycobot_description)/urdf/mycobot_pro_630/link4.dae"/>
      </geometry>
    <origin xyz = "0 0 0.041 " rpy = " -1.5707 0 1.5707"/>
    </collision>
  </link>


  <link name="link5">
    <visual>
      <geometry>
       <mesh filename="file://$(find mycobot_description)/urdf/mycobot_pro_630/link5.dae"/>
      </geometry>
    <origin xyz = "-0.043 0  0 " rpy = " 0  -1.5707 3.1415926"/>
    </visual>
     <collision>
      <geometry>
       <mesh filename="file://$(find mycobot_description)/urdf/mycobot_pro_630/link5.dae"/>
      </geometry>
    <origin xyz = "-0.043 0  0 " rpy = " 0  -1.5707 3.1415926"/>
    </collision>
  </link>

  <link name="link6">
    <visual>
      <geometry>
       <mesh filename="file://$(find mycobot_description)/urdf/mycobot_pro_630/link6.dae"/>
      </geometry>
      <!-- <material name = "grey">
        <color rgba = "0.5 0.5 0.5 1"/>
      </material> -->
    <origin xyz = "0.01 0 0" rpy = " 0 1.5707  0"/>
    </visual>
     <collision>
     <geometry>
       <mesh filename="file://$(find mycobot_description)/urdf/mycobot_pro_630/link6.dae"/>
      </geometry>
      <!-- <material name = "grey">
        <color rgba = "0.5 0.5 0.5 1"/>
      </material> -->
    <origin xyz = "0.01 0 0" rpy = " 0 1.5707  0"/>
    </collision>
  </link>

  <!-- GRIPPER -->
	<link name="gripper_base">
		<inertial>
			<origin xyz="0 0 0.0" rpy="0 0 0"/>
		  	<mass value="0.07"/>
		  	<inertia
				ixx="0.000010725" ixy="0.0" ixz="0.0"
				iyy="0.000014392" iyz="0.0"
				izz="0.000018517"/>
		</inertial>
		<visual>
		  	<geometry>
				<mesh filename="file://$(find mycobot_description)/urdf/mycobot_pro_630/gripper_base.dae"/>
		  	</geometry>
		  	<origin xyz = "0.0 0.0 -0.012" rpy = "0 0 0"/>
		</visual>
		<collision>
		   	<geometry>	
		   		<box size="0.065 0.025 0.025"/>
		  	</geometry>
		  	<origin xyz = "0.0 0.0 0.0" rpy = "0 0 0"/>
		</collision>
	</link>

	<link name="gripper_left1">
		<inertial>
			<origin xyz="0 0 0.0" rpy="0 0 0"/>
		  	<mass value="0.007"/>
		  	<inertia
				ixx="1e-6" ixy="0.0" ixz="0.0"
				iyy="1e-6" iyz="0.0"
				izz="1e-6"/>
		</inertial>
		<visual>
		  	<geometry>
		  		<mesh filename="file://$(find mycobot_description)/urdf/mycobot_pro_630/gripper_left1.dae"/>
		  	</geometry>
			<origin xyz = "0.039 -0.0133 -0.012 " rpy = " 0 0 0"/>
		</visual>
		<collision>
		  	<geometry>
		   		<box size="0.013 0.02 0.015"/>
		  	</geometry>
			<origin xyz = "0.013 0.042 -0.010 " rpy = " 0 0 0"/>
		</collision>
	</link>
	
	<link name="gripper_left2">
		<inertial>
			<origin xyz="0 0 0.0" rpy="0 0 0"/>
		  	<mass value="0.007"/>
		  	<inertia
				ixx="1e-6" ixy="0.0" ixz="0.0"
				iyy="1e-6" iyz="0.0"
				izz="1e-6"/>
		</inertial>
		<visual>
		  	<geometry>
		   		<mesh filename="file://$(find mycobot_description)/urdf/mycobot_pro_630/gripper_left2.dae"/>
		  	</geometry>
			<origin xyz = "0.005 -0.0195 -0.012 " rpy = " 0 0 0"/>
		</visual>
		<collision>
		  	<geometry>
		   		<box size="0.02 0.02 0.02"/>
		  	</geometry>
			<origin xyz = "-0.025 0.0 -0.010 " rpy = " 0 0 0"/>
		</collision>
	</link>
	
	<link name="gripper_left3">
		<inertial>
			<origin xyz="0 0 0.0" rpy="0 0 0"/>
		  	<mass value="0.007"/>
		  	<inertia
				ixx="1e-6" ixy="0.0" ixz="0.0"
				iyy="1e-6" iyz="0.0"
				izz="1e-6"/>
		</inertial>
		<visual>
		  	<geometry>
		   		<mesh filename="file://$(find mycobot_description)/urdf/mycobot_pro_630/gripper_left3.dae"/>
		  	</geometry>
		<origin xyz = "0.012 0.0025 -0.012 " rpy = " 0 0 0"/>
		</visual>
		<collision>
		  	<geometry>
		   		<box size="0.01 0.01 0.01"/>
		  	</geometry>
			<origin xyz = "-0.014 0.005 0.005 " rpy = " 0 0 0"/>
		</collision>
	</link>
	
	<link name="gripper_right1">
		<inertial>
			<origin xyz="0 0 0.0" rpy="0 0 0"/>
		  	<mass value="0.007"/>
		  	<inertia
				ixx="1e-6" ixy="0.0" ixz="0.0"
				iyy="1e-6" iyz="0.0"
				izz="1e-6"/>
		</inertial>
		<visual>
			<geometry>
		   		<mesh filename="file://$(find mycobot_description)/urdf/mycobot_pro_630/gripper_right1.dae"/>
		  	</geometry>
			<origin xyz = "-0.039 -0.0133 -0.012 " rpy = " 0 0 0"/>
		</visual>
		<collision>
		  	<geometry>
		   		<box size="0.013 0.02 0.015"/>
		  	</geometry>
			<origin xyz = "-0.013 0.042 -0.010 " rpy = " 0 0 0"/>
		</collision>
	</link>
	
	<link name="gripper_right2">
		<inertial>
			<origin xyz="0 0 0.0" rpy="0 0 0"/>
		  	<mass value="0.007"/>
		  	<inertia
				ixx="1e-6" ixy="0.0" ixz="0.0"
				iyy="1e-6" iyz="0.0"
				izz="1e-6"/>
		</inertial>
		<visual>
			<geometry>
		   		<mesh filename="file://$(find mycobot_description)/urdf/mycobot_pro_630/gripper_right2.dae"/>
		 	</geometry>
			<origin xyz = "-0.005 -0.0195 -0.012 " rpy = " 0 0 0"/>
		</visual>
		<collision>
		  	<geometry>
		   		<box size="0.02 0.02 0.02"/>
		  	</geometry>
			<origin xyz = "0.025 0.0 -0.010 " rpy = " 0 0 0"/>
		</collision>
	</link>
	
	<link name="gripper_right3">
		<inertial>
			<origin xyz="0 0 0.0" rpy="0 0 0"/>
		  	<mass value="0.007"/>
		  	<inertia
				ixx="1e-6" ixy="0.0" ixz="0.0"
				iyy="1e-6" iyz="0.0"
				izz="1e-6"/>
		</inertial>
		<visual>
			<geometry>
		   		<mesh filename="file://$(find mycobot_description)/urdf/mycobot_pro_630/gripper_right3.dae"/>
			</geometry>
			<origin xyz = "-0.012 0.0025 -0.012 " rpy = " 0 0 0"/>
		</visual>
		<collision>
		  	<geometry>
		   		<box size="0.01 0.01 0.01"/>
		  	</geometry>
			<origin xyz = "0.014 0.005 0.005 " rpy = " 0 0 0"/>
		</collision>
	</link>


  <!-- JOINTS -->

  <joint name="base_to_link1" type="revolute">
    <axis xyz="0 0 1"/>
    <limit effort = "1000.0" lower = "-3.14" upper = "3.14159" velocity = "0"/>
    <parent link="base"/>
    <child link="link1"/>
    <origin xyz= "0 0 0.22934" rpy = "0 0 0"/>  
  </joint>


  <joint name="link1_to_link2" type="revolute">
    <axis xyz="0 0 -1"/>
    <limit effort = "1000.0" lower = "-4.71" upper = "1.5707" velocity = "0"/>
    <parent link="link1"/>
    <child link="link2"/>
    <origin xyz= "0 0  0" rpy = "1.5707 0 0"/>
  </joint>


  <joint name="link2_to_link3" type="revolute">
    <axis xyz=" 0 0 -1"/>
    <limit effort = "1000.0" lower = "-2.61" upper = "2.618" velocity = "0"/>
    <parent link="link2"/>
    <child link="link3"/>
    <origin xyz= "0.27 0 0   " rpy = "0 0 0"/>  
  </joint>

  <joint name="link3_to_link4" type="revolute">
    <axis xyz=" 0 0 -1"/>
    <limit effort = "1000.0" lower = "-4.53" upper = "1.3962" velocity = "0"/>
    <parent link="link3"/>
    <child link="link4"/>
    <origin xyz= "0.267 0  -0.0745" rpy = "0 0 0"/>  
  </joint>

  <joint name="link4_to_link5" type="revolute">
    <axis xyz="0 0 1"/>
    <limit effort = "1000.0" lower = "-2.93" upper = "2.9321" velocity = "0"/>
    <parent link="link4"/>
    <child link="link5"/>
    <origin xyz= "0 -0.095 0.002" rpy = "1.5707 -1.5707 0"/>  
  </joint>

  <joint name="link5_to_link6" type="revolute">
    <axis xyz="-1 0 0"/>
    <limit effort = "1000.0" lower = "-3.03" upper = "3.0368" velocity = "0"/>
    <parent link="link5"/>
    <child link="link6"/>
    <origin xyz= "-0.054 0 0" rpy = "-1.5707 0 0 "/>  
  </joint>

  <!-- GRIPPER -->
  <joint name="link6_to_gripper_base" type="fixed">
		<parent link="link6"/>
		<child link="gripper_base"/>
		<!-- <origin xyz= "-0.015 0 0" rpy = "0 -1.5707 0"/> -->
		<origin xyz= "-0.03 0 0" rpy = "1.5707 1.5707 3.142"/>
	</joint>

	<joint name="gripper_controller" type="revolute">
		<axis xyz="0 0 1"/>
		<limit effort = "5.0" lower = "-0.7" upper = "0.15" velocity = "2.792527"/>
		<parent link="gripper_base"/>
		<child link="gripper_left3"/>
		<origin xyz= "-0.012 0.005 0" rpy = "0 0 0"/> 
	</joint>
	
	<!-- The mimic element means this joint will follow the movements of the 
		gripper_controller joint. 
	-->
	<joint name="gripper_base_to_gripper_left2" type="revolute">
		<axis xyz="0 0 1"/>
		<limit effort = "5.0" lower = "-0.8" upper = "0.5" velocity = "2.792527"/>
		<parent link="gripper_base"/>
		<child link="gripper_left2"/>
		<origin xyz= "-0.005 0.027 0" rpy = "0 0 0"/> 
		<mimic joint="gripper_controller" multiplier="1.0" offset="0" />
	</joint>
	
	<joint name="gripper_left3_to_gripper_left1" type="revolute">
		<axis xyz="0 0 1"/>
		<limit effort = "5.0" lower = "-0.5" upper = "0.5" velocity = "2.792527"/>
		<parent link="gripper_left3"/>
		<child link="gripper_left1"/>
		<origin xyz= "-0.027 0.016 0" rpy = "0 0 0"/> 
		<mimic joint="gripper_controller" multiplier="-1.0" offset="0" />
	</joint>
	
	<joint name="gripper_base_to_gripper_right3" type="revolute">
		<axis xyz="0 0 1"/>
		<limit effort = "5.0" lower = "-0.15" upper = "0.7" velocity = "2.792527"/>
		<parent link="gripper_base"/>
		<child link="gripper_right3"/>
		<origin xyz= "0.012 0.005 0" rpy = "0 0 0"/> 
		<mimic joint="gripper_controller" multiplier="-1.0" offset="0" />
	</joint>
	
	<joint name="gripper_base_to_gripper_right2" type="revolute">
		<axis xyz="0 0 1"/>
		<limit effort = "5.0" lower = "-0.5" upper = "0.8" velocity = "2.792527"/>
		<parent link="gripper_base"/>
		<child link="gripper_right2"/>
		<origin xyz= "0.005 0.027 0" rpy = "0 0 0"/> 
		<mimic joint="gripper_controller" multiplier="-1.0" offset="0" />
	</joint>
	
	<joint name="gripper_right3_to_gripper_right1" type="revolute">
		<axis xyz="0 0 1"/>
		<limit effort = "5.0" lower = "-0.5" upper = "0.5" velocity = "2.792527"/>
		<parent link="gripper_right3"/>
		<child link="gripper_right1"/>
		<origin xyz= "0.027 0.016 0" rpy = "0 0 0"/> 
		<mimic joint="gripper_controller" multiplier="1.0" offset="0" />
	</joint>

</robot>
